Workbook

Sheet Иванова
A1: Реализация средств по уходу за кожей и волосами Oriflame
A2: распространителем Ивановой И.И. за май месяц
A3: Средство | B3: Объем (мл) | C3: Цена (у.е.) | D3: Кол-во проданного (шт.) | E3: Выручка (у.е.)
A4: Восстанавливающий крем с ретинолом | B4: 30 | C4: 14.3 | D4: 1 | E4: =D4*C4 -> 14.3
A5: Восстанавливающий шампунь для сухих волос | B5: 200 | C5: 3.1 | D5: 5 | E5: =D5*C5 -> 15.5
A6: Дневной увлажняющий крем | B6: 50 | C6: 3.65 | D6: 4 | E6: =D6*C6 -> 14.6
A7: Крем для рук | B7: 100 | C7: 2 | D7: 12 | E7: =D7*C7 -> 24
A8: Крем для тела Divine | B8: 250 | C8: 6.3 | D8: 5 | E8: =D8*C8 -> 31.5
A9: Ночной крем с витамином А | B9: 75 | C9: 3.2 | D9: 1 | E9: =D9*C9 -> 3.2
A10: Ночной увлажняющий гель | B10: 50 | C10: 4.2 | D10: 9 | E10: =D10*C10 -> 37.8
A11: Отшелушивающий крем | B11: 150 | C11: 3.9 | D11: 7 | E11: =D11*C11 -> 27.3
A12: Питательный крем для рук и тела | B12: 250 | C12: 6.95 | D12: 5 | E12: =D12*C12 -> 34.75
A13: Питательный ночной крем | B13: 50 | C13: 4.2 | D13: 6 | E13: =D13*C13 -> 25.2
A14: Солнцезащитный крем SPF30 | B14: 100 | C14: 6.65 | D14: 5 | E14: =D14*C14 -> 33.25
A15: Увлажняюший крем для рук и тела | B15: 125 | C15: 7.7 | D15: 4 | E15: =D15*C15 -> 30.8
... A32: Увлажняющий крем-пена для ванн | B32: 300 | C32: 6.95 | D32: 1 | E32: =D32*C32 -> 6.95

Sheet Петрова
A1: Реализация средств по уходу за кожей и волосами Oriflame
A2: распространителем Петровой П.П. за май месяц
A3: Средство | B3: Объем (мл) | C3: Цена (у.е.) | D3: Кол-во проданного (шт.) | E3: Выручка (у.е.)
A4: Восстанавливающий шампунь для сухих волос | B4: 200 | C4: 3.1 | D4: 3 | E4: =D4*C4 -> 9.3
A5: Дневной увлажняющий крем | B5: 50 | C5: 3.65 | D5: 2 | E5: =D5*C5 -> 7.3
A6: Крем для рук | B6: 100 | C6: 2 | D6: 14 | E6: =D6*C6 -> 28
A7: Крем для тела Divine | B7: 250 | C7: 6.3 | D7: 6 | E7: =D7*C7 -> 37.8
A8: Крем для тела Serene | B8: 250 | C8: 6.5 | D8: 5 | E8: =D8*C8 -> 32.5
A9: Крем с витамином E | B9: 125 | C9: 4.25 | D9: 2 | E9: =D9*C9 -> 8.5
A10: Ночной крем с витамином А | B10: 75 | C10: 3.2 | D10: 4 | E10: =D10*C10 -> 12.8
A11: Отшелушивающий крем | B11: 150 | C11: 3.9 | D11: 6 | E11: =D11*C11 -> 23.4
A12: Питательный крем Maximum | B12: 50 | C12: 12.3 | D12: 4 | E12: =D12*C12 -> 49.2
A13: Питательный ночной крем | B13: 50 | C13: 4.2 | D13: 7 | E13: =D13*C13 -> 29.4
A14: Солнцезащитный крем SPF30 | B14: 100 | C14: 6.65 | D14: 3 | E14: =D14*C14 -> 19.95
A15: Увлажняюший крем для рук и тела | B15: 125 | C15: 7.7 | D15: 7 | E15: =D15*C15 -> 53.9
... A29: Увлажняющий крем для ванн | B29: 400 | C29: 4.3 | D29: 4 | E29: =D29*C29 -> 17.2

Sheet Сидорова
A1: Реализация средств по уходу за кожей и волосами Oriflame
A2: распространителем Сидоровой С.С. за май месяц
A3: Средство | B3: Объем (мл) | C3: Цена (у.е.) | D3: Кол-во проданного (шт.) | E3: Выручка (у.е.)
A4: Восстанавливающий крем с ретинолом | B4: 30 | C4: 14.3 | D4: 2 | E4: =D4*C4 -> 28.6
A5: Восстанавливающий шампунь для сухих волос | B5: 200 | C5: 3.1 | D5: 2 | E5: =D5*C5 -> 6.2
A6: Дневной увлажняющий крем | B6: 50 | C6: 3.65 | D6: 8 | E6: =D6*C6 -> 29.2
A7: Крем для рук | B7: 100 | C7: 2 | D7: 10 | E7: =D7*C7 -> 20
A8: Крем для тела Serene | B8: 250 | C8: 6.5 | D8: 7 | E8: =D8*C8 -> 45.5
A9: Крем с витамином E | B9: 125 | C9: 4.25 | D9: 8 | E9: =D9*C9 -> 34
A10: Ночной крем с витамином А | B10: 75 | C10: 3.2 | D10: 7 | E10: =D10*C10 -> 22.4
A11: Ночной увлажняющий гель | B11: 50 | C11: 4.2 | D11: 2 | E11: =D11*C11 -> 8.4
A12: Отшелушивающий крем | B12: 150 | C12: 3.9 | D12: 8 | E12: =D12*C12 -> 31.2
A13: Питательный крем для рук и тела | B13: 250 | C13: 6.95 | D13: 4 | E13: =D13*C13 -> 27.8
A14: Питательный ночной крем | B14: 50 | C14: 4.2 | D14: 2 | E14: =D14*C14 -> 8.4
A15: Увлажняющий крем с оттенком загара | B15: 50 | C15: 4 | D15: 5 | E15: =D15*C15 -> 20
... A29: Увлажняющий крем-пена для ванн | B29: 300 | C29: 6.95 | D29: 2 | E29: =D29*C29 -> 13.9

Sheet Итого
A1: Средство | B1: Кол-во проданного (шт.) | C1: Выручка (у.е.)
B2: Кол-во проданного (шт.) | C2: Выручка (у.е.)
B3: =[1]Иванова!$D$4 -> 1 | C3: =[1]Иванова!$E$4 -> 14.3
B4: =[1]Сидорова!$D$4 -> 2 | C4: =[1]Сидорова!$E$4 -> 28.6
A5: Восстанавливающий крем с ретинолом | B5: =SUM(B3:B4) -> 3 | C5: =SUM(C3:C4) -> 42.9
B6: =[1]Иванова!$D$5 -> 5 | C6: =[1]Иванова!$E$5 -> 15.5
B7: =[1]Петрова!$D$4 -> 3 | C7: =[1]Петрова!$E$4 -> 9.3
B8: =[1]Сидорова!$D$5 -> 2 | C8: =[1]Сидорова!$E$5 -> 6.2
A9: Восстанавливающий шампунь для сухих волос | B9: =SUM(B6:B8) -> 10 | C9: =SUM(C6:C8) -> 31
B10: =[1]Иванова!$D$6 -> 4 | C10: =[1]Иванова!$E$6 -> 14.6
B11: =[1]Петрова!$D$5 -> 2 | C11: =[1]Петрова!$E$5 -> 7.3
B12: =[1]Сидорова!$D$6 -> 8 | C12: =[1]Сидорова!$E$6 -> 29.2
A13: Дневной увлажняющий крем | B13: =SUM(B10:B12) -> 14 | C13: =SUM(C10:C12) -> 51.1
B14: =[1]Иванова!$D$7 -> 12 | C14: =[1]Иванова!$E$7 -> 24
B15: =[1]Петрова!$D$6 -> 14 | C15: =[1]Петрова!$E$6 -> 28
B16: =[1]Сидорова!$D$7 -> 10 | C16: =[1]Сидорова!$E$7 -> 20
A17: Крем для рук | B17: =SUM(B14:B16) -> 36 | C17: =SUM(C14:C16) -> 72
B18: =[1]Иванова!$D$8 -> 5 | C18: =[1]Иванова!$E$8 -> 31.5
B19: =[1]Петрова!$D$7 -> 6 | C19: =[1]Петрова!$E$7 -> 37.8
A20: Крем для тела Divine | B20: =SUM(B18:B19) -> 11 | C20: =SUM(C18:C19) -> 69.3
B21: =[1]Петрова!$D$8 -> 5 | C21: =[1]Петрова!$E$8 -> 32.5
B22: =[1]Сидорова!$D$8 -> 7 | C22: =[1]Сидорова!$E$8 -> 45.5
A23: Крем для тела Serene | B23: =SUM(B21:B22) -> 12 | C23: =SUM(C21:C22) -> 78
B24: =[1]Петрова!$D$9 -> 2 | C24: =[1]Петрова!$E$9 -> 8.5
B25: =[1]Сидорова!$D$9 -> 8 | C25: =[1]Сидорова!$E$9 -> 34
A26: Крем с витамином E | B26: =SUM(B24:B25) -> 10 | C26: =SUM(C24:C25) -> 42.5
B27: =[1]Иванова!$D$9 -> 1 | C27: =[1]Иванова!$E$9 -> 3.2
B28: =[1]Петрова!$D$10 -> 4 | C28: =[1]Петрова!$E$10 -> 12.8
B29: =[1]Сидорова!$D$10 -> 7 | C29: =[1]Сидорова!$E$10 -> 22.4
A30: Ночной крем с витамином А | B30: =SUM(B27:B29) -> 12 | C30: =SUM(C27:C29) -> 38.4
B31: =[1]Иванова!$D$10 -> 9 | C31: =[1]Иванова!$E$10 -> 37.8
B32: =[1]Сидорова!$D$11 -> 2 | C32: =[1]Сидорова!$E$11 -> 8.4
A33: Ночной увлажняющий гель | B33: =SUM(B31:B32) -> 11 | C33: =SUM(C31:C32) -> 46.2
B34: =[1]Иванова!$D$11 -> 7 | C34: =[1]Иванова!$E$11 -> 27.3
B35: =[1]Петрова!$D$11 -> 6 | C35: =[1]Петрова!$E$11 -> 23.4
B36: =[1]Сидорова!$D$12 -> 8 | C36: =[1]Сидорова!$E$12 -> 31.2
A37: Отшелушивающий крем | B37: =SUM(B34:B36) -> 21 | C37: =SUM(C34:C36) -> 81.9
B38: =[1]Иванова!$D$12 -> 5 | C38: =[1]Иванова!$E$12 -> 34.75
B39: =[1]Сидорова!$D$13 -> 4 | C39: =[1]Сидорова!$E$13 -> 27.8
A40: Питательный крем для рук и тела | B40: =SUM(B38:B39) -> 9 | C40: =SUM(C38:C39) -> 62.55
...
